Workbook

Sheet pivot_source
A3: (empty) | B3: reported_Salinity
A4: short_remark | B4: (empty) | C4: Total Result
A5: Data from original source
A6: Data provided by Dr. Felix Elling
A7: Data retrieved from Bale et al. (2019) AEM
A8: Data retrieved from Tierney dataset
A9: GDGT fractions digitized from the figure in the original paper
A10: Total Result

Sheet Sheet1
A1: reported_Temp | B1: - all -
A2: reported_Salinity | B2: - all -
A4: NCBI_family | B4: GTDB_class | C4: GTDB_order | D4: Count of sampleName
A5: f__Nitrosopumilaceae | D5: 4
B6: c__Nitrososphaeria | D6: 4
C7: o__Nitrososphaerales | D7: 4
A8: x__Nitrososphaerota incertae sedis | D8: 1
B9: c__Nitrososphaeria | D9: 1
C10: o__Nitrososphaerales | D10: 1
A11: f__ | D11: 22
B12: c__Nitrososphaeria | D12: 22
C13: o__Nitrososphaerales | D13: 22
A14: f__Acidilobaceae | D14: 16
B15: c__Thermoprotei_A | D15: 16
C16: o__Sulfolobales | D16: 16
A17: f__Cenarchaeaceae | D17: 1
B18: c__Nitrososphaeria | D18: 1
C19: o__Nitrososphaerales | D19: 1
A20: f__Desulfurococcaceae | D20: 2
B21: c__Thermoprotei_A | D21: 2
C22: o__Sulfolobales | D22: 2
A23: f__Nitrosopumilaceae | D23: 100
B24: c__Nitrososphaeria | D24: 100
C25: o__Nitrososphaerales | D25: 100
A26: f__Nitrososphaeraceae | D26: 10
B27: c__Nitrososphaeria | D27: 10
C28: o__Nitrososphaerales | D28: 10
A29: f__Picrophilaceae | D29: 26
B30: c__Thermoplasmata | D30: 26
C31: o__Thermoplasmatales | D31: 26
A32: f__Sulfolobaceae | D32: 2
B33: c__Thermoprotei_A | D33: 2
C34: o__Sulfolobales | D34: 2
A35: f__Thermoproteaceae | D35: 2
B36: c__Thermoprotei | D36: 2
C37: o__Thermoproteales | D37: 2
A38: f__Ca. Nitrosocaldaceae | D38: 2
B39: c__Nitrososphaeria | D39: 2
C40: o__Nitrososphaerales | D40: 2
A41: Total Result | D41: 188

Sheet Frac_isoGDGTs

Sheet Strain_IDs
A1: organism_reported_names | B1: phyloT_leaf_order | C1: GTDB_phyloT_leaf_order | D1: Strains | E1: GTDB ID | F1: PhyloT_ID | G1: NCBI ID | H1: organism_broadClass2 | I1: organism_broadClass3 | J1: fCren_prime vs fCren trend | K1: seawater temperature at sampling depth (°C) | L1: average sampling water depth (m) | M1: reported sampling depth range | N1: temperature optimum | O1: Isolate from | P1: Geographic location | Q1: Source | R1: DOI | S1: 16S_rRNA_accessionID | T1: amoA_gene_accessionID | U1: chromosome_complete_accessionID
A2: Nitrosopumilus oxyclinae HCE1 | B2: 7 | C2: 1 | D2: HCE1 | E2: GCF_013407165.1 | F2: RS_GCF_013407165.1 | G2: 1959104 | H2: Group 1.1a | I2: Group 1.1a-Nitrosopumilus | J2: SCM1-like; High cren/low cren' | L2: 17 | M2: 17 m | O2: the lower euphotic zone of coastal waters | Q2: Qin et al. (2015) | R2: https://doi.org/10.1073/pnas.1501568112 | S2: NR_159207.1 | T2: KX950755.1 | U2: NZ_CP026994.1
A3: Nitrosopumilus cobalaminigenes HCA1 | B3: 9 | C3: 2 | D3: HCA1 | E3: GCF_013407145.1 | F3: RS_GCF_013407145.1 | G3: 1470066 | H3: Group 1.1a | I3: Group 1.1a-Nitrosopumilus | J3: SCM1-like; High cren/low cren' | L3: 50 | M3: 50 m | O3: Seawater samples for enrichment were collected from 50-m water depth at the Puget Sound Regional Synthesis Model (PRISM) Station P10 (47.91 N, 122.62 W) in Hood Canal, Washington, in October 2008. (Hood Canal station P10 - Oligotrophic AOA) | Q3: Qin et al. (2015) | R3: https://doi.org/10.1073/pnas.1501568112 | S3: NR_159206.1 | T3: KX950754.1 | U3: NZ_CP026993.1
A4: Cand. Nitrosomarinus catalina SPOT1 | C4: 3 | D4: SPOT1 | E4: GCF_002156965.1 | F4: RS_GCF_002156965.1 | G4: 1898749 | U4: NZ_CP021324.1
A5: Nitrosopumilus ureiphilus PS0 | B5: 3 | C5: 4 | D5: PS0 | E5: GCF_013407185.1 | F5: RS_GCF_013407185.1 | G5: 1470067 | H5: Group 1.1a | I5: Group 1.1a-Nitrosopumilus | J5: SCM1-like; High cren/low cren' | L5: 0 | M5: 0 m (on a beach) | O5: Seawater samples for enrichment of ammonia oxidizing archaea (AOA) were collected from Puget Sound surface sediment on a beach in August 2006 (Puget Sound main basin - oligotrophic AOA) | Q5: Qin et al. (2015) | R5: https://doi.org/10.1073/pnas.1501568112 | S5: NR_159208.1 | T5: KX950756.1 | U5: NZ_CP026995.1
A6: Nitrosopumilus adriaticus NF5 | B6: 6 | C6: 5 | D6: NF5 | E6: GCF_000956175.1 | F6: RS_GCF_000956175.1 | G6: 1580092 | H6: Group 1.1a | I6: Group 1.1a-Nitrosopumilus | J6: NAOA2-like; Low cren/high cren' | K6: 15.5 | L6: 0.5 | M6: 0.5 m | O6: Northern Adriatic coastal surface water sampled off Piran (Bayer et al., 2016 ISME) - November 2011 | P6: Northern Adriatic Sea | Q6: Elling et al. (2017) | R6: https://doi.org/10.1111/1462-2920.13759 | S6: NR_177395.1 | U6: NZ_CP011070.1
A7: Nitrosopumilus adriaticus CCS1 | C7: 5.1 | D7: CCS1 | U7: NZ_CP167059.1
A8: Ca. Nitrosopumilus sp. NAOA2 | B8: 20 | C8: 5.2 | D8: NAOA2 | G8: 1701109 | H8: Group 1.1a | I8: Group 1.1a-Nitrosopumilus | J8: NAOA2-like; Low cren/high cren' | K8: 14.9 | L8: 5 | M8: 5 m | O8: isolated from surface water samples from the Benguela upwelling system at station GeoB 12802 (NAOA2; 5 m water depth; in situ temperature 14.9 °C; 25°30′ S, 13°27′E) taken during R/V Meteor cruise M76/1 in 2008 (Zabel et al., 2008) | Q8: Elling et al. (2015) | R8: https://doi.org/10.1016/j.gca.2015.09.004 | S8: KT380501.1 | T8: KT380499.1
A9: Nitrosopumilus koreensis AR1 | B9: 2 | C9: 6 | D9: AR1 | E9: GCF_000299365.1 | F9: RS_GCF_000299365.1 | G9: 1229908 | H9: Group 1.1a | I9: Group 1.1a-Nitrosopumilus | J9: Intermediate between SCM1-like and NAOA2-like | L9: 78 | M9: 78 m | O9: Marine sediments (ca. 100 g of sediment from a depth of 0 to 1 cm) collected from Svalbard (Arctic region, 016°28′E, 78°21′N; depth, 78 m) | P9: Svalbard | Q9: Pitcher et al. (2011) | R9: https://doi.org/10.1128/AEM.02758-10 | U9: CP003842.1
A10: Nitrosopumilus maritimus SCM1 | B10: 4 | C10: 7 | D10: SCM1 | E10: GCF_000018465.1 | F10: RS_GCF_000018465.1 | G10: 338192 | H10: Group 1.1a | I10: Group 1.1a-Nitrosopumilus | J10: SCM1-like; High cren/low cren' | O10: a tropical marine fish tank at the Seattle Aquarium in Seattle | P10: Washington | Q10: Elling et al. (2015) | R10: https://doi.org/10.1016/j.gca.2015.09.004 | S10: JQ346765.1 | T10: EU239959.1 | U10: CP000866.1
A11: Ca. Nitrosopumilus sp. NAOA6 | B11: 5 | C11: 7.1 | D11: NAOA6 | H11: Group 1.1a | I11: Group 1.1a-Nitrosopumilus | J11: NAOA2-like; Low cren/high cren' | K11: 13.6 | L11: 5 | M11: 5 m | O11: isolated from surface water samples from the Benguela upwelling system at station GeoB 12806 (NAOA6; 5 m; 13.6 °C; 25°S, 14°23′E) taken during R/V Meteor cruise M76/1 in 2008 (Zabel et al., 2008) | Q11: Elling et al. (2015) | R11: https://doi.org/10.1016/j.gca.2015.09.004 | S11: KT380502.1 | T11: KT380500.1
A12: Nitrosopumilus piranensis D3C | B12: 1 | C12: 8 | D12: D3C | E12: GCF_000875775.1 | F12: RS_GCF_000875775.1 | G12: 1582439 | H12: Group 1.1a | I12: Group 1.1a-Nitrosopumilus | J12: Intermediate between SCM1-like and NAOA2-like | K12: 13.1 | L12: 0.5 | M12: 0.5 m | O12: Northern Adriatic Sea surface water (Bayer et al., 2016 ISME) - December 2011 | P12: Northern Adriatic Sea | Q12: Elling et al. (2017) | R12: https://doi.org/10.1111/1462-2920.13759 | S12: NR_177396.1 | U12: CP010868.1
A13: Nitrosopumilus sp. SJ | B13: 8 | C13: 8.1 | D13: SJ | G13: 1027374 | H13: Group 1.1a | I13: Group 1.1a-Nitrosopumilus | J13: Intermediate between SCM1-like and NAOA2-like | L13: 650 | M13: 650 m | O13: Marine sediments (ca. 100 g of sediment from a depth of 0 to 1 cm) collected from Donghae (128°35′E, 38°20′N; depth, 650 m) | P13: South Korea | Q13: Pitcher et al. (2011) | R13: https://doi.org/10.1128/AEM.02758-10
A14: Nitrosarchaeum koreense MY1 | B14: 10 | C14: 9 | D14: MY1T | E14: GCF_000220175.1 | F14: RS_GCF_000220175.1 | G14: 1088740 | H14: Group 1.1a | I14: Group 1.1a-Nitrosopumilus | J14: SCM1-like; High cren/low cren' | O14: Soil of an experimental agricultural station at the Chungbuk Natinonal University (Jung MY et al. 2011 AEM) | P14: South Korea | Q14: Jung et al. (2011) | R14: https://doi.org/10.1128/AEM.05787-11 | S14: NR_177299.1 | T14: HQ331117.1
A15: Ca. Nitrosarchaeum limnia SFB1 | B15: 11 | C15: 10 | D15: SFB1 | E15: GCA_000204585.1 | F15: GB_GCA_000204585.1 | G15: 1007084 | H15: Group 1.1a | I15: Group 1.1a-Nitrosopumilus | J15: SCM1-like; High cren/low cren' | K15: 21.6 | L15: 5 | M15: 5 m (read from https://www.ncei.noaa.gov/maps/bathymetry/) | O15: sediments (0-5 cm) collected in northern part of the San Francisco Bay estuary (site SU001S; 38°5′55.75″N, 122° 2′47.40″W) in 2006 (Mosier and Francis 2008 Envi. Microbio.) | P15: San Francisco Bay | Q15: Pitcher et al. (2011) | R15: https://doi.org/10.1128/AEM.02758-10 | U15: CM001158.1
A16: Cenarchaeum symbiosum A | B16: 19 | C16: 11 | D16: A | E16: GCA_000200715.1 | F16: GB_GCA_000200715.1 | G16: 46770 | H16: Group 1.1a | I16: Group 1.1a-Nitrosopumilus | J16: High Cren/No Cren' | L16: 15 | M16: 10 to 20 m | O16: Sponges were collected at depths of 10-20 m by SCUBA divingat two different sites located just offshore of Santa Barbara,CA. (Preston, Molinski, and DeLong (1996) PNAS) | P16: Santa Barbara Bay, CA | Q16: Sinninghe Damste et al. (2002) | R16: 10.1194/jlr.m200148-jlr200 | U16: DP000238.1
A17: Nitropelagicus brevis CN25 | C17: 12 | D17: CN25 | E17: GCF_000812185.1 | F17: RS_GCF_000812185.1 | U17: CP007026.1
A18: Ca. Nitrosotenuis uzonensis N4 | B18: 18 | C18: 13 | D18: N4 | E18: GCF_000723185.1 | F18: RS_GCF_000723185.1 | G18: 1407055 | H18: Group 1.1a | I18: Group 1.1a-Nitrosopumilus | J18: NAOA2-like; Low cren/high cren' | O18: thermal spring | P18: Kamchatka | Q18: Bale et al. (2019) | R18: https://doi.org/10.1128/AEM.01332-19
A19: Ca. Nitrosotenuis chungbukensis MY2 | B19: 17 | C19: 14 | D19: MY2 | E19: GCF_030518575.1 | F19: RS_GCF_030518575.1 | G19: 1353246 | H19: Group 1.1a | I19: Group 1.1a-Nitrosopumilus | J19: SCM1-like; High cren/low cren' | O19: a deep oligotrophic soil horizon | P19: South Korea | Q19: Jung et al. (2014) | R19: https://doi.org/10.1128/AEM.03730-13
A20: Ca. Nitrososphaera gargensis Ga9.2 | B20: 14 | C20: 15 | D20: Ga9.2 | E20: GCF_000303155.1 | F20: RS_GCF_000303155.1 | G20: 497727 | H20: Group 1.1b | I20: Group 1.1b-Nitrososphaera | J20: Hot spring-like/High Cren' | O20: microbial mat sample from the Garga hot spring in the Buryat Republic (Hatzenpichler et al., 2008) | P20: Russia | Q20: Elling et al. (2017) | R20: https://doi.org/10.1111/1462-2920.13759 | U20: CP002408.1
A21: Nitrososphaera viennensis EN76 | B21: 12 | C21: 16 | D21: EN76 | E21: GCF_000698785.1 | F21: RS_GCF_000698785.1 | G21: 1034015 | H21: Group 1.1b | I21: Group 1.1b-Nitrososphaera | J21: Hot spring-like/High Cren' | O21: isolated from garden soil in Vienna (Tourna M et al. 2011. PNAS) | P21: Austria | Q21: Sinninghe Damste et al. (2012) | R21: https://doi.org/10.1128/AEM.01681-12 | S21: FR773157.1 | T21: FR773159.1 | U21: CP007536.1
A22: Ca. Nitrosocosmicus oleophilus MY3 | B22: 15 | C22: 17 | D22: MY3 | E22: GCF_000802205.1 | F22: RS_GCF_000802205.1 | G22: 1353260 | H22: Group 1.1b | I22: Group 1.1b-Nitrososphaera | J22: SCM1-like; High cren/low cren' | O22: surface sediment rich in decaying forest-leaf litter and contaminated by hydrocarbons characteristic of coal-tar waste | P22: South Korea | Q22: Jung et al. (2016) | R22: https://doi.org/10.1111/1758-2229.12477 | U22: CP012850.1
A23: Metallosphaera sedula DSM 5348 | B23: 27 | C23: 18 | D23: DSM 5348 | E23: GCA_000016605.1 | F23: GB_GCA_000016605.1 | G23: 43687 | H23: Sulfolobaceae | I23: Sulfolobaceae | J23: No Cren/Cren' | O23: hot water pond | P23: Naples, Pisciarelli Solfatara, Italy | Q23: Pearson et al. (2008) | R23: https://doi.org/10.1128/AEM.02450-07 | S23: NR_074387.1 | U23: CP000682.1
A24: Sulfolobus solfataricus P2 | B24: 26 | C24: 19 | D24: P2 | E24: GCF_000007005.1 | F24: RS_GCF_000007005.1 | G24: 273057 | H24: Sulfolobaceae | I24: Sulfolobaceae | J24: No Cren/Cren' | O24: volcanic hot spring | P24: Campi flegrei, Pisciarelli near Agnano, Italy | Q24: Pearson et al. (2008) | R24: https://doi.org/10.1128/AEM.02450-07 | U24: AE006641.1
A25: Desulfurococcus amylolyticus DSM 16532 | B25: 29 | C25: 20 | D25: DSM 16532 | E25: GCF_000231015.2 | F25: RS_GCF_000231015.2 | G25: 94694 | H25: Desulfurococcaceae | I25: Desulfurococcaceae | J25: No Cren/Cren' | O25: freshwater hot spring | P25: Kamchatka Peninsula, Uzon caldera | Q25: Pearson et al. (2008) | R25: https://doi.org/10.1128/AEM.02450-07 | S25: NR_042810.1 | U25: NC_018001.1
A26: Desulfurococcus amylolyticus Z-533 | B26: 28 | C26: 20 | D26: Z-533 (or DSM 3822) | E26: GCF_000513855.1 | F26: RS_GCF_000513855.1 | G26: 94694 | H26: Desulfurococcaceae | I26: Desulfurococcaceae | J26: No Cren/Cren' | O26: hot spring | P26: Kamchatka | Q26: Pearson et al. (2008) | R26: https://doi.org/10.1128/AEM.02450-07 | S26: NR_114559.1
A27: Acidilobus saccharovorans 345-15 | B27: 21 | C27: 21 | D27: 345-15 | E27: GCF_000144915.1 | F27: RS_GCF_000144915.1 | G27: 242703 | H27: Acidilobaceae | I27: Acidilobaceae | J27: No Cren/Cren' | O27: mixture of water and mud from an acidic terrestrial hot pool | P27: Kamchatka | Q27: Pearson et al. (2008) | R27: https://doi.org/10.1128/AEM.02450-07 | S27: NR_102933.1 | U27: CP001742.1
A28: Thermoproteus uzoniensis Z-605 | B28: 25 | C28: 22 | D28: DSM 5263; Z-605 (768-20) | E28: GCF_000193375.1 | F28: RS_GCF_000193375.1 | G28: 184117 | H28: Thermoproteaceae | I28: Thermoproteaceae | J28: No Cren/Cren' | Q28: Pearson et al. (2008) | R28: https://doi.org/10.1128/AEM.02450-07 | S28: NR_177322.1 | U28: CP002590.1
A29: Vulcanisaeta moutnovskia 768-28 | B29: 24 | C29: 23 | D29: 768-28 | E29: GCF_000190315.1 | F29: RS_GCF_000190315.1 | G29: 985053 | H29: Thermoproteaceae | I29: Thermoproteaceae | J29: No Cren/Cren' | Q29: Pearson et al. (2008) | R29: https://doi.org/10.1128/AEM.02450-07 | U29: CP002529.1
A30: Picrophulus oshimae | B30: 30 | C30: 24 | D30: DSM 9790 | E30: GCF_900176435.1 | F30: RS_GCF_900176435.1 | G30: 82076 | H30: Picrophilaceae | I30: Picrophilaceae | J30: Small Cren/No Cren' | O30: Solfataric field | P30: Hokkaido | Q30: Feyhl-Buska et al. (2016) | R30: https://doi.org/10.3389/fmicb.2016.01323 | S30: NR_074187.1 | U30: NC_005877.1
A31: Ca Nitrososphaera JG1 | B31: 13 | C31: 25.1 | D31: JG1 | G31: 1110358 | H31: Group 1.1b | I31: Group 1.1b-Nitrososphaera | J31: NAOA2-like; Low cren/high cren' | O31: Strain JG1 was also enriched from a soil sample from a Capsicum annuum cultivation field from the same agricultural station of the Chungbuk National University (Kim JG et al. 2012 AEM) | P31: South Korea | Q31: Sinninghe Damste et al. (2012) | R31: https://doi.org/10.1128/AEM.01681-12 | S31: JF748724.1 | T31: JF748723.1
A32: Ca. Nitrosocaldus yellowstonensis HL72 | B32: 16 | C32: 25.1 | D32: HL72 | G32: 1268556 | H32: HWCG-III | I32: HWCG-III-Nitrosocaldus | J32: Intermediate between SCM1-like and NAOA2-like | O32: hotspring, Yellowstone National Park, USA (de la Torre et al.,2008) | P32: USA | Q32: Elling et al. (2017) | R32: https://doi.org/10.1111/1462-2920.13759
A33: Acidilobus aceticus 1904 | B33: 22 | C33: 25.1 | D33: 1904 | G33: 105851 | H33: Acidilobaceae | I33: Acidilobaceae | J33: No Cren/Cren' | O33: continental hot vents | P33: Kamchatka | Q33: Pearson et al. (2008) | R33: https://doi.org/10.1128/AEM.02450-07 | S33: NR_041774.1
A34: Acidilobus sulfurireducens | B34: 23 | C34: 25.1 | D34: 7A | G34: 411357 | H34: Acidilobaceae | I34: Acidilobaceae | J34: SCM1-like; High cren/low cren' | O34: geothermal spring in Yellowstone National Park | P34: Wyoming, USA | Q34: Boyd et al. (2011) | R34: 10.1007/s00792-010-0339-y

Sheet master_cultures
A1: sampleName | B1: Strains | C1: organism_reported_names | D1: phyloT_order | E1: GTDB_phylum | F1: GTDB_class | G1: GTDB_order | H1: GTDB_family | I1: GTDB_genus | J1: GTDB_species | K1: NCBI_phylum | L1: NCBI_class | M1: NCBI_order | N1: NCBI_family | O1: NCBI_genus | P1: NCBI_species | Q1: organism_broadClass | R1: organism_broadClass2 | S1: organism_broadClass3 | T1: organism_genomes_combined_WGS_PGS | U1: isolate_from | V1: geographic_location | W1: sampleID_new | X1: reported_Temp | Y1: reported_Salinity | Z1: reported_pH | AA1: reported_oxy_micromolar | AB1: reported_ammonium | AC1: reported_ionicStrength | AD1: reported_AOR_umol_NO2_l_d | AE1: reported_growthPhase_growthRate | AF1: experiment_setup | AG1: Broad Filtration Class | AH1: Lipid Extractions | AI1: Filter pore size | AJ1: LCMS_instrumentation | AK1: sum_reported_fractions | AL1: reported_1302 | AM1: reported_1300 | AN1: reported_1298 | AO1: reported_1296 | AP1: reported_1292 | AQ1: reported_1292_iso | AR1: reported_1294 | AS1: reported_1290 | AT1: reported_1288 | AU1: reported_1286 | AV1: reported_1292_iso2 | AW1: reported_1294_iso | AX1: reported_1290_iso | AY1: reported_1288_iso | AZ1: reported_1286_iso | BA1: fGDGT_0 | BB1: fGDGT_1 | BC1: fGDGT_2 | BD1: fGDGT_3 | BE1: fGDGT_cren | BF1: fGDGT_cren_prime | BG1: BITindex | BH1: dataType_level0 | BI1: dataType_level1 | BJ1: Source | BK1: short_remark | BL1: full_remark | BM1: duplicate_Datasets | BN1: incomplete_GDGT_fractions | BO1: BIT_QC_above05 | BP1: gdgt0Cren_QC_above07 | BQ1: MI_QC_above05 | BR1: QC_Indices_check | BS1: detectionLimit_check | BT1: Source2 | BU1: firstAuthor_firstName | BV1: DOI | BW1: Taxonomy data update
A2: Bale2019_001_Cultures_ThAOA_Ca_Nitrosotenuis uzonesis_P-GDGT_DH_37 | B2: N4 | C2: Ca. Nitrosotenuis uzonensis N4 | D2: =INDEX(Strain_IDs!C:C,MATCH(Table1[[#This Row],[Strains]],Strain_IDs!D:D,0)) -> 13 | E2: p__Thermoproteota | F2: c__Nitrososphaeria | G2: o__Nitrososphaerales | H2: f__Nitrosopumilaceae | I2: g__Nitrosotenuis | K2: p__Nitrososphaerota | L2: c__Nitrososphaeria | M2: o__Nitrosopumilales | N2: f__ | O2: g__Nitrosotenuis | Q2: Terrestrial thermophile | R2: Group 1.1a | S2: Group 1.1a-Nitrosopumilus | T2: sequenced | W2: RR_culture_001 | X2: 37 | AF2: Culture-temperature | AG2: IPL-GDGTs | AH2: IPL-GDGT (reported); 2G (Dihexose) | AJ2: NP-HPLC-ESI-Ion Trap-MS | AK2: =SUM(Table1[[#This Row],[reported_1302]:[reported_1286_iso]]) -> 25.4 | AL2: 0 | AM2: 0.6 | AN2: 2.8 | AO2: 5 | AP2: 4 | AQ2: 0 | AR2: 13 | BA2: =AL2/SUM($AL2:$AQ2) -> 0 | BB2: =AM2/SUM($AL2:$AQ2) -> 0.048387097 | BC2: =AN2/SUM($AL2:$AQ2) -> 0.22580645 | BD2: =AO2/SUM($AL2:$AQ2) -> 0.40322581 | BE2: =AP2/SUM($AL2:$AQ2) -> 0.32258065 | BF2: =AQ2/SUM($AL2:$AQ2) -> 0 | BG2: =#N/A -> #N/A | BH2: Culture | BI2: Culture - ThAOA | BJ2: Bale et al. (2019) AEM | BK2: Data from original source | BL2: Data from original source; average abundance from 4 replicates | BM2: No | BN2: No | BO2: Not reported; Assumed no brGDGTs (cultures) | BP2: No | BQ2: Yes | BR2: Fail | BS2: Fail | BT2: Bale et al. (2019) | BU2: Nicole | BV2: https://doi.org/10.1128/AEM.01332-19 | BW2: GTDB Release 214.1; NCBI (retrieved from February 21, 2024)
A3: Bale2019_002_Cultures_ThAOA_Ca_Nitrosotenuis uzonesis_P-GDGT_DH_46 | B3: N4 | C3: Ca. Nitrosotenuis uzonensis N4 | D3: =INDEX(Strain_IDs!C:C,MATCH(Table1[[#This Row],[Strains]],Strain_IDs!D:D,0)) -> 13 | E3: p__Thermoproteota | F3: c__Nitrososphaeria | G3: o__Nitrososphaerales | H3: f__Nitrosopumilaceae | I3: g__Nitrosotenuis | K3: p__Nitrososphaerota | L3: c__Nitrososphaeria | M3: o__Nitrosopumilales | N3: f__ | O3: g__Nitrosotenuis | Q3: Terrestrial thermophile | R3: Group 1.1a | S3: Group 1.1a-Nitrosopumilus | T3: sequenced | W3: RR_culture_002 | X3: 46 | AF3: Culture-temperature | AG3: IPL-GDGTs | AH3: IPL-GDGT (reported); 2G (Dihexose) | AJ3: NP-HPLC-ESI-Ion Trap-MS | AK3: =SUM(Table1[[#This Row],[reported_1302]:[reported_1286_iso]]) -> 28.7 | AL3: 0 | AM3: 0.3 | AN3: 1.9 | AO3: 4.5 | AP3: 11 | AQ3: 0 | AR3: 11 | BA3: =AL3/SUM($AL3:$AQ3) -> 0 | BB3: =AM3/SUM($AL3:$AQ3) -> 0.016949153 | BC3: =AN3/SUM($AL3:$AQ3) -> 0.10734463 | BD3: =AO3/SUM($AL3:$AQ3) -> 0.25423729 | BE3: =AP3/SUM($AL3:$AQ3) -> 0.62146893 | BF3: =AQ3/SUM($AL3:$AQ3) -> 0 | BG3: =#N/A -> #N/A | BH3: Culture | BI3: Culture - ThAOA | BJ3: Bale et al. (2019) AEM | BK3: Data from original source | BL3: Data from original source; average abundance from 4 replicates | BM3: No | BN3: No | BO3: Not reported; Assumed no brGDGTs (cultures) | BP3: No | BQ3: No | BR3: Pass | BS3: Fail | BT3: Bale et al. (2019) | BU3: Nicole | BV3: https://doi.org/10.1128/AEM.01332-19 | BW3: GTDB Release 214.1; NCBI (retrieved from February 21, 2024)
A4: Bale2019_003_Cultures_ThAOA_Ca_Nitrosotenuis uzonesis_P-GDGT_DH_50 | B4: N4 | C4: Ca. Nitrosotenuis uzonensis N4 | D4: =INDEX(Strain_IDs!C:C,MATCH(Table1[[#This Row],[Strains]],Strain_IDs!D:D,0)) -> 13 | E4: p__Thermoproteota | F4: c__Nitrososphaeria | G4: o__Nitrososphaerales | H4: f__Nitrosopumilaceae | I4: g__Nitrosotenuis | K4: p__Nitrososphaerota | L4: c__Nitrososphaeria | M4: o__Nitrosopumilales | N4: f__ | O4: g__Nitrosotenuis | Q4: Terrestrial thermophile | R4: Group 1.1a | S4: Group 1.1a-Nitrosopumilus | T4: sequenced | W4: RR_culture_003 | X4: 50 | AF4: Culture-temperature | AG4: IPL-GDGTs | AH4: IPL-GDGT (reported); 2G (Dihexose) | AJ4: NP-HPLC-ESI-Ion Trap-MS | AK4: =SUM(Table1[[#This Row],[reported_1302]:[reported_1286_iso]]) -> 35.6 | AL4: 0 | AM4: 0.1 | AN4: 2.8 | AO4: 5.7 | AP4: 14 | AQ4: 0 | AR4: 13 | BA4: =AL4/SUM($AL4:$AQ4) -> 0 | BB4: =AM4/SUM($AL4:$AQ4) -> 0.0044247788 | BC4: =AN4/SUM($AL4:$AQ4) -> 0.12389381 | BD4: =AO4/SUM($AL4:$AQ4) -> 0.25221239 | BE4: =AP4/SUM($AL4:$AQ4) -> 0.61946903 | BF4: =AQ4/SUM($AL4:$AQ4) -> 0 | BG4: =#N/A -> #N/A | BH4: Culture | BI4: Culture - ThAOA | BJ4: Bale et al. (2019) AEM | BK4: Data from original source | BL4: Data from original source; average abundance from 4 replicates | BM4: No | BN4: No | BO4: Not reported; Assumed no brGDGTs (cultures) | BP4: No | BQ4: No | BR4: Pass | BS4: Fail | BT4: Bale et al. (2019) | BU4: Nicole | BV4: https://doi.org/10.1128/AEM.01332-19 | BW4: GTDB Release 214.1; NCBI (retrieved from February 21, 2024)
A5: Bale2019_004_Cultures_ThAOA_Ca_Nitrosotenuis uzonesis_P-GDGT_HPH_37 | B5: N4 | C5: Ca. Nitrosotenuis uzonensis N4 | D5: =INDEX(Strain_IDs!C:C,MATCH(Table1[[#This Row],[Strains]],Strain_IDs!D:D,0)) -> 13 | E5: p__Thermoproteota | F5: c__Nitrososphaeria | G5: o__Nitrososphaerales | H5: f__Nitrosopumilaceae | I5: g__Nitrosotenuis | K5: p__Nitrososphaerota | L5: c__Nitrososphaeria | M5: o__Nitrosopumilales | N5: f__ | O5: g__Nitrosotenuis | Q5: Terrestrial thermophile | R5: Group 1.1a | S5: Group 1.1a-Nitrosopumilus | T5: sequenced | W5: RR_culture_004 | X5: 37 | AF5: Culture-temperature | AG5: IPL-GDGTs | AH5: IPL-GDGT (reported); HPH | AJ5: NP-HPLC-ESI-Ion Trap-MS | AK5: =SUM(Table1[[#This Row],[reported_1302]:[reported_1286_iso]]) -> 36 | AL5: 7 | AM5: 9.2 | AN5: 3.8 | AO5: 1.8 | AP5: 14 | AQ5: 0 | AR5: 0.2 | BA5: =AL5/SUM($AL5:$AQ5) -> 0.19553073 | BB5: =AM5/SUM($AL5:$AQ5) -> 0.25698324 | BC5: =AN5/SUM($AL5:$AQ5) -> 0.10614525 | BD5: =AO5/SUM($AL5:$AQ5) -> 0.05027933 | BE5: =AP5/SUM($AL5:$AQ5) -> 0.39106145 | BF5: =AQ5/SUM($AL5:$AQ5) -> 0 | BG5: =#N/A -> #N/A | BH5: Culture | BI5: Culture - ThAOA | BJ5: Bale et al. (2019) AEM | BK5: Data from original source | BL5: Data from original source; average abundance from 4 replicates | BM5: No | BN5: No | BO5: Not reported; Assumed no brGDGTs (cultures) | BP5: No | BQ5: Yes | BR5: Fail | BS5: Fail | BT5: Bale et al. (2019) | BU5: Nicole | BV5: https://doi.org/10.1128/AEM.01332-19 | BW5: GTDB Release 214.1; NCBI (retrieved from February 21, 2024)
A6: Bale2019_005_Cultures_ThAOA_Ca_Nitrosotenuis uzonesis_P-GDGT_HPH_46 | B6: N4 | C6: Ca. Nitrosotenuis uzonensis N4 | D6: =INDEX(Strain_IDs!C:C,MATCH(Table1[[#This Row],[Strains]],Strain_IDs!D:D,0)) -> 13 | E6: p__Thermoproteota | F6: c__Nitrososphaeria | G6: o__Nitrososphaerales | H6: f__Nitrosopumilaceae | I6: g__Nitrosotenuis | K6: p__Nitrososphaerota | L6: c__Nitrososphaeria | M6: o__Nitrosopumilales | N6: f__ | O6: g__Nitrosotenuis | Q6: Terrestrial thermophile | R6: Group 1.1a | S6: Group 1.1a-Nitrosopumilus | T6: sequenced | W6: RR_culture_005 | X6: 46 | AF6: Culture-temperature | AG6: IPL-GDGTs | AH6: IPL-GDGT (reported); HPH | AJ6: NP-HPLC-ESI-Ion Trap-MS | AK6: =SUM(Table1[[#This Row],[reported_1302]:[reported_1286_iso]]) -> 33.2 | AL6: 0.7 | AM6: 1.4 | AN6: 1.3 | AO6: 0.8 | AP6: 29 | AQ6: 0 | AR6: 0 | BA6: =AL6/SUM($AL6:$AQ6) -> 0.021084337 | BB6: =AM6/SUM($AL6:$AQ6) -> 0.042168675 | BC6: =AN6/SUM($AL6:$AQ6) -> 0.039156627 | BD6: =AO6/SUM($AL6:$AQ6) -> 0.024096386 | BE6: =AP6/SUM($AL6:$AQ6) -> 0.87349398 | BF6: =AQ6/SUM($AL6:$AQ6) -> 0 | BG6: =#N/A -> #N/A | BH6: Culture | BI6: Culture - ThAOA | BJ6: Bale et al. (2019) AEM | BK6: Data from original source | BL6: Data from original source; average abundance from 4 replicates | BM6: No | BN6: No | BO6: Not reported; Assumed no brGDGTs (cultures) | BP6: No | BQ6: No | BR6: Pass | BS6: Fail | BT6: Bale et al. (2019) | BU6: Nicole | BV6: https://doi.org/10.1128/AEM.01332-19 | BW6: GTDB Release 214.1; NCBI (retrieved from February 21, 2024)
A7: Bale2019_006_Cultures_ThAOA_Ca_Nitrosotenuis uzonesis_P-GDGT_HPH_50 | B7: N4 | C7: Ca. Nitrosotenuis uzonensis N4 | D7: =INDEX(Strain_IDs!C:C,MATCH(Table1[[#This Row],[Strains]],Strain_IDs!D:D,0)) -> 13 | E7: p__Thermoproteota | F7: c__Nitrososphaeria | G7: o__Nitrososphaerales | H7: f__Nitrosopumilaceae | I7: g__Nitrosotenuis | K7: p__Nitrososphaerota | L7: c__Nitrososphaeria | M7: o__Nitrosopumilales | N7: f__ | O7: g__Nitrosotenuis | Q7: Terrestrial thermophile | R7: Group 1.1a | S7: Group 1.1a-Nitrosopumilus | T7: sequenced | W7: RR_culture_006 | X7: 50 | AF7: Culture-temperature | AG7: IPL-GDGTs | AH7: IPL-GDGT (reported); HPH | AJ7: NP-HPLC-ESI-Ion Trap-MS | AK7: =SUM(Table1[[#This Row],[reported_1302]:[reported_1286_iso]]) -> 21.9 | AL7: 0.6 | AM7: 1 | AN7: 0.8 | AO7: 0.4 | AP7: 19 | AQ7: 0 | AR7: 0.1 | BA7: =AL7/SUM($AL7:$AQ7) -> 0.027522936 | BB7: =AM7/SUM($AL7:$AQ7) -> 0.04587156 | BC7: =AN7/SUM($AL7:$AQ7) -> 0.036697248 | BD7: =AO7/SUM($AL7:$AQ7) -> 0.018348624 | BE7: =AP7/SUM($AL7:$AQ7) -> 0.87155963 | BF7: =AQ7/SUM($AL7:$AQ7) -> 0 | BG7: =#N/A -> #N/A | BH7: Culture | BI7: Culture - ThAOA | BJ7: Bale et al. (2019) AEM | BK7: Data from original source | BL7: Data from original source; average abundance from 4 replicates | BM7: No | BN7: No | BO7: Not reported; Assumed no brGDGTs (cultures) | BP7: No | BQ7: No | BR7: Pass | BS7: Fail | BT7: Bale et al. (2019) | BU7: Nicole | BV7: https://doi.org/10.1128/AEM.01332-19 | BW7: GTDB Release 214.1; NCBI (retrieved from February 21, 2024)
A8: Bale2019_007_Cultures_ThAOA_Ca_Nitrosotenuis uzonesis_P-GDGT_MH_37 | B8: N4 | C8: Ca. Nitrosotenuis uzonensis N4 | D8: =INDEX(Strain_IDs!C:C,MATCH(Table1[[#This Row],[Strains]],Strain_IDs!D:D,0)) -> 13 | E8: p__Thermoproteota | F8: c__Nitrososphaeria | G8: o__Nitrososphaerales | H8: f__Nitrosopumilaceae | I8: g__Nitrosotenuis | K8: p__Nitrososphaerota | L8: c__Nitrososphaeria | M8: o__Nitrosopumilales | N8: f__ | O8: g__Nitrosotenuis | Q8: Terrestrial thermophile | R8: Group 1.1a | S8: Group 1.1a-Nitrosopumilus | T8: sequenced | W8: RR_culture_007 | X8: 37 | AF8: Culture-temperature | AG8: IPL-GDGTs | AH8: IPL-GDGT (reported); 1G (Hexose) | AJ8: NP-HPLC-ESI-Ion Trap-MS | AK8: =SUM(Table1[[#This Row],[reported_1302]:[reported_1286_iso]]) -> 4.3 | AL8: 0.5 | AM8: 0.6 | AN8: 0.5 | AO8: 0.6 | AP8: 1.6 | AQ8: 0 | AR8: 0.5 | BA8: =AL8/SUM($AL8:$AQ8) -> 0.13157895 | BB8: =AM8/SUM($AL8:$AQ8) -> 0.15789474 | BC8: =AN8/SUM($AL8:$AQ8) -> 0.13157895 | BD8: =AO8/SUM($AL8:$AQ8) -> 0.15789474 | BE8: =AP8/SUM($AL8:$AQ8) -> 0.42105263 | BF8: =AQ8/SUM($AL8:$AQ8) -> 0 | BG8: =#N/A -> #N/A | BH8: Culture | BI8: Culture - ThAOA | BJ8: Bale et al. (2019) AEM | BK8: Data from original source | BL8: Data from original source; average abundance from 4 replicates | BM8: No | BN8: No | BO8: Not reported; Assumed no brGDGTs (cultures) | BP8: No | BQ8: Yes | BR8: Fail | BS8: Fail | BT8: Bale et al. (2019) | BU8: Nicole | BV8: https://doi.org/10.1128/AEM.01332-19 | BW8: GTDB Release 214.1; NCBI (retrieved from February 21, 2024)
A9: Bale2019_008_Cultures_ThAOA_Ca_Nitrosotenuis uzonesis_P-GDGT_MH_46 | B9: N4 | C9: Ca. Nitrosotenuis uzonensis N4 | D9: =INDEX(Strain_IDs!C:C,MATCH(Table1[[#This Row],[Strains]],Strain_IDs!D:D,0)) -> 13 | E9: p__Thermoproteota | F9: c__Nitrososphaeria | G9: o__Nitrososphaerales | H9: f__Nitrosopumilaceae | I9: g__Nitrosotenuis | K9: p__Nitrososphaerota | L9: c__Nitrososphaeria | M9: o__Nitrosopumilales | N9: f__ | O9: g__Nitrosotenuis | Q9: Terrestrial thermophile | R9: Group 1.1a | S9: Group 1.1a-Nitrosopumilus | T9: sequenced | W9: RR_culture_008 | X9: 46 | AF9: Culture-temperature | AG9: IPL-GDGTs | AH9: IPL-GDGT (reported); 1G (Hexose) | AJ9: NP-HPLC-ESI-Ion Trap-MS | AK9: =SUM(Table1[[#This Row],[reported_1302]:[reported_1286_iso]]) -> 5.4 | AL9: 0.2 | AM9: 0.7 | AN9: 0.7 | AO9: 0.9 | AP9: 2.1 | AQ9: 0 | AR9: 0.8 | BA9: =AL9/SUM($AL9:$AQ9) -> 0.043478261 | BB9: =AM9/SUM($AL9:$AQ9) -> 0.15217391 | BC9: =AN9/SUM($AL9:$AQ9) -> 0.15217391 | BD9: =AO9/SUM($AL9:$AQ9) -> 0.19565217 | BE9: =AP9/SUM($AL9:$AQ9) -> 0.45652174 | BF9: =AQ9/SUM($AL9:$AQ9) -> 0 | BG9: =#N/A -> #N/A | BH9: Culture | BI9: Culture - ThAOA | BJ9: Bale et al. (2019) AEM | BK9: Data from original source | BL9: Data from original source; average abundance from 4 replicates | BM9: No | BN9: No | BO9: Not reported; Assumed no brGDGTs (cultures) | BP9: No | BQ9: Yes | BR9: Fail | BS9: Fail | BT9: Bale et al. (2019) | BU9: Nicole | BV9: https://doi.org/10.1128/AEM.01332-19 | BW9: GTDB Release 214.1; NCBI (retrieved from February 21, 2024)
A10: Bale2019_009_Cultures_ThAOA_Ca_Nitrosotenuis uzonesis_P-GDGT_MH_50 | B10: N4 | C10: Ca. Nitrosotenuis uzonensis N4 | D10: =INDEX(Strain_IDs!C:C,MATCH(Table1[[#This Row],[Strains]],Strain_IDs!D:D,0)) -> 13 | E10: p__Thermoproteota | F10: c__Nitrososphaeria | G10: o__Nitrososphaerales | H10: f__Nitrosopumilaceae | I10: g__Nitrosotenuis | K10: p__Nitrososphaerota | L10: c__Nitrososphaeria | M10: o__Nitrosopumilales | N10: f__ | O10: g__Nitrosotenuis | Q10: Terrestrial thermophile | R10: Group 1.1a | S10: Group 1.1a-Nitrosopumilus | T10: sequenced | W10: RR_culture_009 | X10: 50 | AF10: Culture-temperature | AG10: IPL-GDGTs | AH10: IPL-GDGT (reported); 1G (Hexose) | AJ10: NP-HPLC-ESI-Ion Trap-MS | AK10: =SUM(Table1[[#This Row],[reported_1302]:[reported_1286_iso]]) -> 10.2 | AL10: 0.5 | AM10: 0.9 | AN10: 1 | AO10: 0.8 | AP10: 5.7 | AQ10: 0 | AR10: 1.3 | BA10: =AL10/SUM($AL10:$AQ10) -> 0.056179775 | BB10: =AM10/SUM($AL10:$AQ10) -> 0.1011236 | BC10: =AN10/SUM($AL10:$AQ10) -> 0.11235955 | BD10: =AO10/SUM($AL10:$AQ10) -> 0.08988764 | BE10: =AP10/SUM($AL10:$AQ10) -> 0.64044944 | BF10: =AQ10/SUM($AL10:$AQ10) -> 0 | BG10: =#N/A -> #N/A | BH10: Culture | BI10: Culture - ThAOA | BJ10: Bale et al. (2019) AEM | BK10: Data from original source | BL10: Data from original source; average abundance from 4 replicates | BM10: No | BN10: No | BO10: Not reported; Assumed no brGDGTs (cultures) | BP10: No | BQ10: No | BR10: Pass | BS10: Fail | BT10: Bale et al. (2019) | BU10: Nicole | BV10: https://doi.org/10.1128/AEM.01332-19 | BW10: GTDB Release 214.1; NCBI (retrieved from February 21, 2024)
A11: Bale2019_010_Cultures_ThAOA_Ca_Nitrosotenuis uzonesis_P-GDGT_TH1_37 | B11: N4 | C11: Ca. Nitrosotenuis uzonensis N4 | D11: =INDEX(Strain_IDs!C:C,MATCH(Table1[[#This Row],[Strains]],Strain_IDs!D:D,0)) -> 13 | E11: p__Thermoproteota | F11: c__Nitrososphaeria | G11: o__Nitrososphaerales | H11: f__Nitrosopumilaceae | I11: g__Nitrosotenuis | K11: p__Nitrososphaerota | L11: c__Nitrososphaeria | M11: o__Nitrosopumilales | N11: f__ | O11: g__Nitrosotenuis | Q11: Terrestrial thermophile | R11: Group 1.1a | S11: Group 1.1a-Nitrosopumilus | T11: sequenced | W11: RR_culture_010 | X11: 37 | AF11: Culture-temperature | AG11: IPL-GDGTs | AH11: IPL-GDGT (reported); TH1 | AJ11: NP-HPLC-ESI-Ion Trap-MS | AK11: =SUM(Table1[[#This Row],[reported_1302]:[reported_1286_iso]]) -> 22.3 | AL11: 0 | AM11: 0.8 | AN11: 3.4 | AO11: 7.1 | AP11: 1.1 | AQ11: 0 | AR11: 9.9 | BA11: =AL11/SUM($AL11:$AQ11) -> 0 | BB11: =AM11/SUM($AL11:$AQ11) -> 0.064516129 | BC11: =AN11/SUM($AL11:$AQ11) -> 0.27419355 | BD11: =AO11/SUM($AL11:$AQ11) -> 0.57258065 | BE11: =AP11/SUM($AL11:$AQ11) -> 0.088709677 | BF11: =AQ11/SUM($AL11:$AQ11) -> 0 | BG11: =#N/A -> #N/A | BH11: Culture | BI11: Culture - ThAOA | BJ11: Bale et al. (2019) AEM | BK11: Data from original source | BL11: Data from original source; average abundance from 4 replicates | BM11: No | BN11: No | BO11: Not reported; Assumed no brGDGTs (cultures) | BP11: No | BQ11: Yes | BR11: Fail | BS11: Fail | BT11: Bale et al. (2019) | BU11: Nicole | BV11: https://doi.org/10.1128/AEM.01332-19 | BW11: GTDB Release 214.1; NCBI (retrieved from February 21, 2024)
A12: Bale2019_011_Cultures_ThAOA_Ca_Nitrosotenuis uzonesis_P-GDGT_TH1_46 | B12: N4 | C12: Ca. Nitrosotenuis uzonensis N4 | D12: =INDEX(Strain_IDs!C:C,MATCH(Table1[[#This Row],[Strains]],Strain_IDs!D:D,0)) -> 13 | E12: p__Thermoproteota | F12: c__Nitrososphaeria | G12: o__Nitrososphaerales | H12: f__Nitrosopumilaceae | I12: g__Nitrosotenuis | K12: p__Nitrososphaerota | L12: c__Nitrososphaeria | M12: o__Nitrosopumilales | N12: f__ | O12: g__Nitrosotenuis | Q12: Terrestrial thermophile | R12: Group 1.1a | S12: Group 1.1a-Nitrosopumilus | T12: sequenced | W12: RR_culture_011 | X12: 46 | AF12: Culture-temperature | AG12: IPL-GDGTs | AH12: IPL-GDGT (reported); TH1 | AJ12: NP-HPLC-ESI-Ion Trap-MS | AK12: =SUM(Table1[[#This Row],[reported_1302]:[reported_1286_iso]]) -> 22.6 | AL12: 0 | AM12: 0.1 | AN12: 2.6 | AO12: 6.1 | AP12: 2.8 | AQ12: 0 | AR12: 11 | BA12: =AL12/SUM($AL12:$AQ12) -> 0 | BB12: =AM12/SUM($AL12:$AQ12) -> 0.0086206897 | BC12: =AN12/SUM($AL12:$AQ12) -> 0.22413793 | BD12: =AO12/SUM($AL12:$AQ12) -> 0.52586207 | BE12: =AP12/SUM($AL12:$AQ12) -> 0.24137931 | BF12: =AQ12/SUM($AL12:$AQ12) -> 0 | BG12: =#N/A -> #N/A | BH12: Culture | BI12: Culture - ThAOA | BJ12: Bale et al. (2019) AEM | BK12: Data from original source | BL12: Data from original source; average abundance from 4 replicates | BM12: No | BN12: No | BO12: Not reported; Assumed no brGDGTs (cultures) | BP12: No | BQ12: Yes | BR12: Fail | BS12: Fail | BT12: Bale et al. (2019) | BU12: Nicole | BV12: https://doi.org/10.1128/AEM.01332-19 | BW12: GTDB Release 214.1; NCBI (retrieved from February 21, 2024)
A13: Bale2019_012_Cultures_ThAOA_Ca_Nitrosotenuis uzonesis_P-GDGT_TH1_50 | B13: N4 | C13: Ca. Nitrosotenuis uzonensis N4 | D13: =INDEX(Strain_IDs!C:C,MATCH(Table1[[#This Row],[Strains]],Strain_IDs!D:D,0)) -> 13 | E13: p__Thermoproteota | F13: c__Nitrososphaeria | G13: o__Nitrososphaerales | H13: f__Nitrosopumilaceae | I13: g__Nitrosotenuis | K13: p__Nitrososphaerota | L13: c__Nitrososphaeria | M13: o__Nitrosopumilales | N13: f__ | O13: g__Nitrosotenuis | Q13: Terrestrial thermophile | R13: Group 1.1a | S13: Group 1.1a-Nitrosopumilus | T13: sequenced | W13: RR_culture_012 | X13: 50 | AF13: Culture-temperature | AG13: IPL-GDGTs | AH13: IPL-GDGT (reported); TH1 | AJ13: NP-HPLC-ESI-Ion Trap-MS | AK13: =SUM(Table1[[#This Row],[reported_1302]:[reported_1286_iso]]) -> 23.9 | AL13: 0 | AM13: 0 | AN13: 1.8 | AO13: 5.2 | AP13: 4.9 | AQ13: 0 | AR13: 12 | BA13: =AL13/SUM($AL13:$AQ13) -> 0 | BB13: =AM13/SUM($AL13:$AQ13) -> 0 | BC13: =AN13/SUM($AL13:$AQ13) -> 0.1512605 | BD13: =AO13/SUM($AL13:$AQ13) -> 0.43697479 | BE13: =AP13/SUM($AL13:$AQ13) -> 0.41176471 | BF13: =AQ13/SUM($AL13:$AQ13) -> 0 | BG13: =#N/A -> #N/A | BH13: Culture | BI13: Culture - ThAOA | BJ13: Bale et al. (2019) AEM | BK13: Data from original source | BL13: Data from original source; average abundance from 4 replicates | BM13: No | BN13: No | BO13: Not reported; Assumed no brGDGTs (cultures) | BP13: No | BQ13: Yes | BR13: Fail | BS13: Fail | BT13: Bale et al. (2019) | BU13: Nicole | BV13: https://doi.org/10.1128/AEM.01332-19 | BW13: GTDB Release 214.1; NCBI (retrieved from February 21, 2024)
... A19: Bale2019_018_Cultures_ThAOA_Ca_Nitrosotenuis uzonesis_P-GDGT_HPH_50 | B19: N4 | C19: Ca. Nitrosotenuis uzonensis N4 | D19: =INDEX(Strain_IDs!C:C,MATCH(Table1[[#This Row],[Strains]],Strain_IDs!D:D,0)) -> 13 | E19: p__Thermoproteota | F19: c__Nitrososphaeria | G19: o__Nitrososphaerales | H19: f__Nitrosopumilaceae | I19: g__Nitrosotenuis | K19: p__Nitrososphaerota | L19: c__Nitrososphaeria | M19: o__Nitrosopumilales | N19: f__ | O19: g__Nitrosotenuis | Q19: Terrestrial thermophile | R19: Group 1.1a | S19: Group 1.1a-Nitrosopumilus | T19: sequenced | W19: RR_culture_018 | X19: 50 | AF19: Culture-temperature | AG19: IPL-GDGTs | AH19: Total IPLs (calculated) | AJ19: NP-HPLC-ESI-Ion Trap-MS | AK19: =SUM(Table1[[#This Row],[reported_1302]:[reported_1286_iso]]) -> 68.8 | AL19: 1.1 | AM19: 2 | AN19: 6.4 | AO19: 12.1 | AP19: 47.1 | AQ19: 0 | AR19: 0.1 | BA19: =AL19/SUM($AL19:$AQ19) -> 0.016011645 | BB19: =AM19/SUM($AL19:$AQ19) -> 0.029112082 | BC19: =AN19/SUM($AL19:$AQ19) -> 0.093158661 | BD19: =AO19/SUM($AL19:$AQ19) -> 0.17612809 | BE19: =AP19/SUM($AL19:$AQ19) -> 0.68558952 | BF19: =AQ19/SUM($AL19:$AQ19) -> 0 | BG19: =#N/A -> #N/A | BH19: Culture | BI19: Culture - ThAOA | BJ19: Bale et al. (2019) AEM | BK19: Data from original source | BL19: Data from original source; calculated from IPL fractions - assume ND as 0 | BM19: No | BN19: No | BO19: Not reported; Assumed no brGDGTs (cultures) | BP19: No | BQ19: No | BR19: Pass | BS19: Fail | BT19: Bale et al. (2019) | BU19: Nicole | BV19: https://doi.org/10.1128/AEM.01332-19 | BW19: GTDB Release 214.1; NCBI (retrieved from February 21, 2024)
A20: Bale2019_019_Cultures_ThAOA_Ca_Nitrosotenuis uzonesis_C-GDGT_37 | B20: N4 | C20: Ca. Nitrosotenuis uzonensis N4 | D20: =INDEX(Strain_IDs!C:C,MATCH(Table1[[#This Row],[Strains]],Strain_IDs!D:D,0)) -> 13 | E20: p__Thermoproteota | F20: c__Nitrososphaeria | G20: o__Nitrososphaerales | H20: f__Nitrosopumilaceae | I20: g__Nitrosotenuis | K20: p__Nitrososphaerota | L20: c__Nitrososphaeria | M20: o__Nitrosopumilales | N20: f__ | O20: g__Nitrosotenuis | Q20: Terrestrial thermophile | R20: Group 1.1a | S20: Group 1.1a-Nitrosopumilus | T20: sequenced | W20: RR_culture_019 | X20: 37 | AF20: Culture-temperature | AG20: Total GDGTs | AH20: Total GDGTs (Hydrolyzed B-D extracts; CLs + cleaved IPLs) | AJ20: NP-HPLC-APCI-Single Quad-MS | AK20: =SUM(Table1[[#This Row],[reported_1302]:[reported_1286_iso]]) -> 89.7 | AL20: 5.3 | AM20: 11 | AN20: 3.4 | AO20: 7.1 | AP20: 25 | AQ20: 4.6 | AR20: 28 | AW20: 5.3 | BA20: =AL20/SUM($AL20:$AQ20) -> 0.093971631 | BB20: =AM20/SUM($AL20:$AQ20) -> 0.19503546 | BC20: =AN20/SUM($AL20:$AQ20) -> 0.060283688 | BD20: =AO20/SUM($AL20:$AQ20) -> 0.12588652 | BE20: =AP20/SUM($AL20:$AQ20) -> 0.44326241 | BF20: =AQ20/SUM($AL20:$AQ20) -> 0.081560284 | BG20: =#N/A -> #N/A | BH20: Culture | BI20: Culture - ThAOA | BJ20: Bale et al. (2019) AEM | BK20: Data from original source | BL20: Data from original source; average abundance from 4 replicates | BM20: No | BN20: No | BO20: Not reported; Assumed no brGDGTs (cultures) | BP20: No | BQ20: No | BR20: Pass | BS20: Pass | BT20: Bale et al. (2019) | BU20: Nicole | BV20: https://doi.org/10.1128/AEM.01332-19 | BW20: GTDB Release 214.1; NCBI (retrieved from February 21, 2024)
A21: Bale2019_020_Cultures_ThAOA_Ca_Nitrosotenuis uzonesis_C-GDGT_46 | B21: N4 | C21: Ca. Nitrosotenuis uzonensis N4 | D21: =INDEX(Strain_IDs!C:C,MATCH(Table1[[#This Row],[Strains]],Strain_IDs!D:D,0)) -> 13 | E21: p__Thermoproteota | F21: c__Nitrososphaeria | G21: o__Nitrososphaerales | H21: f__Nitrosopumilaceae | I21: g__Nitrosotenuis | K21: p__Nitrososphaerota | L21: c__Nitrososphaeria | M21: o__Nitrosopumilales | N21: f__ | O21: g__Nitrosotenuis | Q21: Terrestrial thermophile | R21: Group 1.1a | S21: Group 1.1a-Nitrosopumilus | T21: sequenced | W21: RR_culture_020 | X21: 46 | AF21: Culture-temperature | AG21: Total GDGTs | AH21: Total GDGTs (Hydrolyzed B-D extracts; CLs + cleaved IPLs) | AJ21: NP-HPLC-APCI-Single Quad-MS | AK21: =SUM(Table1[[#This Row],[reported_1302]:[reported_1286_iso]]) -> 93.8 | AL21: 0.4 | AM21: 3.9 | AN21: 1.4 | AO21: 2.9 | AP21: 51 | AQ21: 12 | AR21: 16 | AW21: 6.2 | BA21: =AL21/SUM($AL21:$AQ21) -> 0.0055865922 | BB21: =AM21/SUM($AL21:$AQ21) -> 0.054469274 | BC21: =AN21/SUM($AL21:$AQ21) -> 0.019553073 | BD21: =AO21/SUM($AL21:$AQ21) -> 0.040502793 | BE21: =AP21/SUM($AL21:$AQ21) -> 0.7122905 | BF21: =AQ21/SUM($AL21:$AQ21) -> 0.16759777 | BG21: =#N/A -> #N/A | BH21: Culture | BI21: Culture - ThAOA | BJ21: Bale et al. (2019) AEM | BK21: Data from original source | BL21: Data from original source; average abundance from 4 replicates | BM21: No | BN21: No | BO21: Not reported; Assumed no brGDGTs (cultures) | BP21: No | BQ21: No | BR21: Pass | BS21: Pass | BT21: Bale et al. (2019) | BU21: Nicole | BV21: https://doi.org/10.1128/AEM.01332-19 | BW21: GTDB Release 214.1; NCBI (retrieved from February 21, 2024)
A22: Bale2019_021_Cultures_ThAOA_Ca_Nitrosotenuis uzonesis_C-GDGT_50 | B22: N4 | C22: Ca. Nitrosotenuis uzonensis N4 | D22: =INDEX(Strain_IDs!C:C,MATCH(Table1[[#This Row],[Strains]],Strain_IDs!D:D,0)) -> 13 | E22: p__Thermoproteota | F22: c__Nitrososphaeria | G22: o__Nitrososphaerales | H22: f__Nitrosopumilaceae | I22: g__Nitrosotenuis | K22: p__Nitrososphaerota | L22: c__Nitrososphaeria | M22: o__Nitrosopumilales | N22: f__ | O22: g__Nitrosotenuis | Q22: Terrestrial thermophile | R22: Group 1.1a | S22: Group 1.1a-Nitrosopumilus | T22: sequenced | W22: RR_culture_021 | X22: 50 | AF22: Culture-temperature | AG22: Total GDGTs | AH22: Total GDGTs (Hydrolyzed B-D extracts; CLs + cleaved IPLs) | AJ22: NP-HPLC-APCI-Single Quad-MS | AK22: =SUM(Table1[[#This Row],[reported_1302]:[reported_1286_iso]]) -> 94.9 | AL22: 0.5 | AM22: 4.8 | AN22: 1.5 | AO22: 2.3 | AP22: 59 | AQ22: 11 | AR22: 11 | AW22: 4.8 | BA22: =AL22/SUM($AL22:$AQ22) -> 0.0063211125 | BB22: =AM22/SUM($AL22:$AQ22) -> 0.06068268 | BC22: =AN22/SUM($AL22:$AQ22) -> 0.018963338 | BD22: =AO22/SUM($AL22:$AQ22) -> 0.029077118 | BE22: =AP22/SUM($AL22:$AQ22) -> 0.74589128 | BF22: =AQ22/SUM($AL22:$AQ22) -> 0.13906448 | BG22: =#N/A -> #N/A | BH22: Culture | BI22: Culture - ThAOA | BJ22: Bale et al. (2019) AEM | BK22: Data from original source | BL22: Data from original source; average abundance from 4 replicates | BM22: No | BN22: No | BO22: Not reported; Assumed no brGDGTs (cultures) | BP22: No | BQ22: No | BR22: Pass | BS22: Pass | BT22: Bale et al. (2019) | BU22: Nicole | BV22: https://doi.org/10.1128/AEM.01332-19 | BW22: GTDB Release 214.1; NCBI (retrieved from February 21, 2024)
A23: Elling2015_Culture_NA0A2_18 | B23: NAOA2 | C23: Ca. Nitrosopumilus sp. NAOA2 | D23: =INDEX(Strain_IDs!C:C,MATCH(Table1[[#This Row],[Strains]],Strain_IDs!D:D,0)) -> 5.2 | E23: p__Thermoproteota | F23: c__Nitrososphaeria | G23: o__Nitrososphaerales | H23: f__Nitrosopumilaceae | I23: g__Nitrosopumilus | K23: p__Nitrososphaerota | L23: c__Nitrososphaeria | M23: o__Nitrosopumilales | N23: f__Nitrosopumilaceae | O23: g__Nitrosopumilus | Q23: Marine mesophile | R23: Group 1.1a | S23: Group 1.1a-Nitrosopumilus | T23: not_sequenced | U23: South Atlantic surface water | V23: South Atlantic; Benguela upwelling system | W23: RR_culture_022 | X23: 18 | Z23: 7.5 | AF23: Culture-temperature | AG23: Total GDGTs | AH23: Total GDGTs; Acid hydrolyzed TLEs (CLs + cleaved IPLs) | AJ23: NP-UHPLC-APCI-qTOF-MS/MS | AK23: =SUM(Table1[[#This Row],[reported_1302]:[reported_1286_iso]]) -> 99.9 | AL23: 10 | AM23: 8.4 | AN23: 14.2 | AO23: 35.3 | AP23: 13.3 | AQ23: 1.3 | AR23: 17.4 | BA23: =AL23/SUM($AL23:$AQ23) -> 0.12121212 | BB23: =AM23/SUM($AL23:$AQ23) -> 0.10181818 | BC23: =AN23/SUM($AL23:$AQ23) -> 0.17212121 | BD23: =AO23/SUM($AL23:$AQ23) -> 0.42787879 | BE23: =AP23/SUM($AL23:$AQ23) -> 0.16121212 | BF23: =AQ23/SUM($AL23:$AQ23) -> 0.015757576 | BG23: =#N/A -> #N/A | BH23: Culture | BI23: Culture - AOA | BJ23: Elling et al. (2015) GCA | BK23: Data from original source | BL23: Data from original source | BM23: No | BN23: No | BO23: Not reported; Assumed no brGDGTs (Cultures) | BP23: No | BQ23: Yes | BR23: Fail | BS23: Pass | BT23: Elling et al. (2015) | BU23: Felix | BV23: https://doi.org/10.1016/j.gca.2015.09.004 | BW23: GTDB Release 214.1; NCBI (retrieved from February 21, 2024)
A24: Elling2015_Culture_NA0A2_22 | B24: NAOA2 | C24: Ca. Nitrosopumilus sp. NAOA2 | D24: =INDEX(Strain_IDs!C:C,MATCH(Table1[[#This Row],[Strains]],Strain_IDs!D:D,0)) -> 5.2 | E24: p__Thermoproteota | F24: c__Nitrososphaeria | G24: o__Nitrososphaerales | H24: f__Nitrosopumilaceae | I24: g__Nitrosopumilus | K24: p__Nitrososphaerota | L24: c__Nitrososphaeria | M24: o__Nitrosopumilales | N24: f__Nitrosopumilaceae | O24: g__Nitrosopumilus | Q24: Marine mesophile | R24: Group 1.1a | S24: Group 1.1a-Nitrosopumilus | T24: not_sequenced | U24: South Atlantic surface water | V24: South Atlantic; Benguela upwelling system | W24: RR_culture_023 | X24: 22 | Z24: 7.5 | AF24: Culture-temperature | AG24: Total GDGTs | AH24: Total GDGTs; Acid hydrolyzed TLEs (CLs + cleaved IPLs) | AJ24: NP-UHPLC-APCI-qTOF-MS/MS | AK24: =SUM(Table1[[#This Row],[reported_1302]:[reported_1286_iso]]) -> 100.1 | AL24: 14.4 | AM24: 9.6 | AN24: 23.3 | AO24: 21.4 | AP24: 17.5 | AQ24: 1.3 | AR24: 12.6 | BA24: =AL24/SUM($AL24:$AQ24) -> 0.16457143 | BB24: =AM24/SUM($AL24:$AQ24) -> 0.10971429 | BC24: =AN24/SUM($AL24:$AQ24) -> 0.26628571 | BD24: =AO24/SUM($AL24:$AQ24) -> 0.24457143 | BE24: =AP24/SUM($AL24:$AQ24) -> 0.2 | BF24: =AQ24/SUM($AL24:$AQ24) -> 0.014857143 | BG24: =#N/A -> #N/A | BH24: Culture | BI24: Culture - AOA | BJ24: Elling et al. (2015) GCA | BK24: Data from original source | BL24: Data from original source | BM24: No | BN24: No | BO24: Not reported; Assumed no brGDGTs (Cultures) | BP24: No | BQ24: Yes | BR24: Fail | BS24: Pass | BT24: Elling et al. (2015) | BU24: Felix | BV24: https://doi.org/10.1016/j.gca.2015.09.004 | BW24: GTDB Release 214.1; NCBI (retrieved from February 21, 2024)
A25: Elling2015_Culture_NA0A2_28 | B25: NAOA2 | C25: Ca. Nitrosopumilus sp. NAOA2 | D25: =INDEX(Strain_IDs!C:C,MATCH(Table1[[#This Row],[Strains]],Strain_IDs!D:D,0)) -> 5.2 | E25: p__Thermoproteota | F25: c__Nitrososphaeria | G25: o__Nitrososphaerales | H25: f__Nitrosopumilaceae | I25: g__Nitrosopumilus | K25: p__Nitrososphaerota | L25: c__Nitrososphaeria | M25: o__Nitrosopumilales | N25: f__Nitrosopumilaceae | O25: g__Nitrosopumilus | Q25: Marine mesophile | R25: Group 1.1a | S25: Group 1.1a-Nitrosopumilus | T25: not_sequenced | U25: South Atlantic surface water | V25: South Atlantic; Benguela upwelling system | W25: RR_culture_024 | X25: 28 | Z25: 7.5 | AF25: Culture-temperature | AG25: Total GDGTs | AH25: Total GDGTs; Acid hydrolyzed TLEs (CLs + cleaved IPLs) | AJ25: NP-UHPLC-APCI-qTOF-MS/MS | AK25: =SUM(Table1[[#This Row],[reported_1302]:[reported_1286_iso]]) -> 100 | AL25: 10.5 | AM25: 7.1 | AN25: 23.1 | AO25: 21.7 | AP25: 23.9 | AQ25: 2.2 | AR25: 11.5 | BA25: =AL25/SUM($AL25:$AQ25) -> 0.11864407 | BB25: =AM25/SUM($AL25:$AQ25) -> 0.080225989 | BC25: =AN25/SUM($AL25:$AQ25) -> 0.26101695 | BD25: =AO25/SUM($AL25:$AQ25) -> 0.24519774 | BE25: =AP25/SUM($AL25:$AQ25) -> 0.2700565 | BF25: =AQ25/SUM($AL25:$AQ25) -> 0.024858757 | BG25: =#N/A -> #N/A | BH25: Culture | BI25: Culture - AOA | BJ25: Elling et al. (2015) GCA | BK25: Data from original source | BL25: Data from original source | BM25: No | BN25: No | BO25: Not reported; Assumed no brGDGTs (Cultures) | BP25: No | BQ25: Yes | BR25: Fail | BS25: Pass | BT25: Elling et al. (2015) | BU25: Felix | BV25: https://doi.org/10.1016/j.gca.2015.09.004 | BW25: GTDB Release 214.1; NCBI (retrieved from February 21, 2024)
A26: Elling2015_Culture_NA0A2_35 | B26: NAOA2 | C26: Ca. Nitrosopumilus sp. NAOA2 | D26: =INDEX(Strain_IDs!C:C,MATCH(Table1[[#This Row],[Strains]],Strain_IDs!D:D,0)) -> 5.2 | E26: p__Thermoproteota | F26: c__Nitrososphaeria | G26: o__Nitrososphaerales | H26: f__Nitrosopumilaceae | I26: g__Nitrosopumilus | K26: p__Nitrososphaerota | L26: c__Nitrososphaeria | M26: o__Nitrosopumilales | N26: f__Nitrosopumilaceae | O26: g__Nitrosopumilus | Q26: Marine mesophile | R26: Group 1.1a | S26: Group 1.1a-Nitrosopumilus | T26: not_sequenced | U26: South Atlantic surface water | V26: South Atlantic; Benguela upwelling system | W26: RR_culture_025 | X26: 35 | Z26: 7.5 | AF26: Culture-temperature | AG26: Total GDGTs | AH26: Total GDGTs; Acid hydrolyzed TLEs (CLs + cleaved IPLs) | AJ26: NP-UHPLC-APCI-qTOF-MS/MS | AK26: =SUM(Table1[[#This Row],[reported_1302]:[reported_1286_iso]]) -> 100.1 | AL26: 8.8 | AM26: 7 | AN26: 10.3 | AO26: 14.5 | AP26: 38.7 | AQ26: 4.9 | AR26: 15.9 | BA26: =AL26/SUM($AL26:$AQ26) -> 0.10451306 | BB26: =AM26/SUM($AL26:$AQ26) -> 0.083135392 | BC26: =AN26/SUM($AL26:$AQ26) -> 0.12232779 | BD26: =AO26/SUM($AL26:$AQ26) -> 0.17220903 | BE26: =AP26/SUM($AL26:$AQ26) -> 0.45961995 | BF26: =AQ26/SUM($AL26:$AQ26) -> 0.058194774 | BG26: =#N/A -> #N/A | BH26: Culture | BI26: Culture - AOA | BJ26: Elling et al. (2015) GCA | BK26: Data from original source | BL26: Data from original source | BM26: No | BN26: No | BO26: Not reported; Assumed no brGDGTs (Cultures) | BP26: No | BQ26: No | BR26: Pass | BS26: Pass | BT26: Elling et al. (2015) | BU26: Felix | BV26: https://doi.org/10.1016/j.gca.2015.09.004 | BW26: GTDB Release 214.1; NCBI (retrieved from February 21, 2024)
A27: Elling2015_Culture_NA0A6_18 | B27: NAOA6 | C27: Ca. Nitrosopumilus sp. NAOA6 | D27: =INDEX(Strain_IDs!C:C,MATCH(Table1[[#This Row],[Strains]],Strain_IDs!D:D,0)) -> 7.1 | E27: p__Thermoproteota | F27: c__Nitrososphaeria | G27: o__Nitrososphaerales | H27: f__Nitrosopumilaceae | I27: g__Nitrosopumilus | K27: p__Nitrososphaerota | L27: c__Nitrososphaeria | M27: o__Nitrosopumilales | N27: f__Nitrosopumilaceae | O27: g__Nitrosopumilus | Q27: Marine mesophile | R27: Group 1.1a | S27: Group 1.1a-Nitrosopumilus | T27: not_sequenced | U27: South Atlantic surface water | V27: South Atlantic; Benguela upwelling system | W27: RR_culture_026 | X27: 18 | Z27: 7.5 | AF27: Culture-temperature | AG27: Total GDGTs | AH27: Total GDGTs; Acid hydrolyzed TLEs (CLs + cleaved IPLs) | AJ27: NP-UHPLC-APCI-qTOF-MS/MS | AK27: =SUM(Table1[[#This Row],[reported_1302]:[reported_1286_iso]]) -> 100 | AL27: 31.2 | AM27: 18.4 | AN27: 14.9 | AO27: 3.7 | AP27: 30.4 | AQ27: 0.2 | AR27: 1.2 | BA27: =AL27/SUM($AL27:$AQ27) -> 0.31578947 | BB27: =AM27/SUM($AL27:$AQ27) -> 0.18623482 | BC27: =AN27/SUM($AL27:$AQ27) -> 0.15080972 | BD27: =AO27/SUM($AL27:$AQ27) -> 0.037449393 | BE27: =AP27/SUM($AL27:$AQ27) -> 0.30769231 | BF27: =AQ27/SUM($AL27:$AQ27) -> 0.0020242915 | BG27: =#N/A -> #N/A | BH27: Culture | BI27: Culture - AOA | BJ27: Elling et al. (2015) GCA | BK27: Data from original source | BL27: Data from original source | BM27: No | BN27: No | BO27: Not reported; Assumed no brGDGTs (Cultures) | BP27: No | BQ27: Yes | BR27: Fail | BS27: Pass | BT27: Elling et al. (2015) | BU27: Felix | BV27: https://doi.org/10.1016/j.gca.2015.09.004 | BW27: GTDB Release 214.1; NCBI (retrieved from February 21, 2024)
A28: Elling2015_Culture_NA0A6_22 | B28: NAOA6 | C28: Ca. Nitrosopumilus sp. NAOA6 | D28: =INDEX(Strain_IDs!C:C,MATCH(Table1[[#This Row],[Strains]],Strain_IDs!D:D,0)) -> 7.1 | E28: p__Thermoproteota | F28: c__Nitrososphaeria | G28: o__Nitrososphaerales | H28: f__Nitrosopumilaceae | I28: g__Nitrosopumilus | K28: p__Nitrososphaerota | L28: c__Nitrososphaeria | M28: o__Nitrosopumilales | N28: f__Nitrosopumilaceae | O28: g__Nitrosopumilus | Q28: Marine mesophile | R28: Group 1.1a | S28: Group 1.1a-Nitrosopumilus | T28: not_sequenced | U28: South Atlantic surface water | V28: South Atlantic; Benguela upwelling system | W28: RR_culture_027 | X28: 22 | Z28: 7.5 | AF28: Culture-temperature | AG28: Total GDGTs | AH28: Total GDGTs; Acid hydrolyzed TLEs (CLs + cleaved IPLs) | AJ28: NP-UHPLC-APCI-qTOF-MS/MS | AK28: =SUM(Table1[[#This Row],[reported_1302]:[reported_1286_iso]]) -> 99.9 | AL28: 12.2 | AM28: 9.6 | AN28: 22.1 | AO28: 19.8 | AP28: 24.3 | AQ28: 1.6 | AR28: 10.3 | BA28: =AL28/SUM($AL28:$AQ28) -> 0.13616071 | BB28: =AM28/SUM($AL28:$AQ28) -> 0.10714286 | BC28: =AN28/SUM($AL28:$AQ28) -> 0.24665179 | BD28: =AO28/SUM($AL28:$AQ28) -> 0.22098214 | BE28: =AP28/SUM($AL28:$AQ28) -> 0.27120536 | BF28: =AQ28/SUM($AL28:$AQ28) -> 0.017857143 | BG28: =#N/A -> #N/A | BH28: Culture | BI28: Culture - AOA | BJ28: Elling et al. (2015) GCA | BK28: Data from original source | BL28: Data from original source | BM28: No | BN28: No | BO28: Not reported; Assumed no brGDGTs (Cultures) | BP28: No | BQ28: Yes | BR28: Fail | BS28: Pass | BT28: Elling et al. (2015) | BU28: Felix | BV28: https://doi.org/10.1016/j.gca.2015.09.004 | BW28: GTDB Release 214.1; NCBI (retrieved from February 21, 2024)
A29: Elling2015_Culture_NA0A6_28 | B29: NAOA6 | C29: Ca. Nitrosopumilus sp. NAOA6 | D29: =INDEX(Strain_IDs!C:C,MATCH(Table1[[#This Row],[Strains]],Strain_IDs!D:D,0)) -> 7.1 | E29: p__Thermoproteota | F29: c__Nitrososphaeria | G29: o__Nitrososphaerales | H29: f__Nitrosopumilaceae | I29: g__Nitrosopumilus | K29: p__Nitrososphaerota | L29: c__Nitrososphaeria | M29: o__Nitrosopumilales | N29: f__Nitrosopumilaceae | O29: g__Nitrosopumilus | Q29: Marine mesophile | R29: Group 1.1a | S29: Group 1.1a-Nitrosopumilus | T29: not_sequenced | U29: South Atlantic surface water | V29: South Atlantic; Benguela upwelling system | W29: RR_culture_028 | X29: 28 | Z29: 7.5 | AF29: Culture-temperature | AG29: Total GDGTs | AH29: Total GDGTs; Acid hydrolyzed TLEs (CLs + cleaved IPLs) | AJ29: NP-UHPLC-APCI-qTOF-MS/MS | AK29: =SUM(Table1[[#This Row],[reported_1302]:[reported_1286_iso]]) -> 99.9 | AL29: 7.5 | AM29: 5.9 | AN29: 27 | AO29: 11.3 | AP29: 40.9 | AQ29: 1.2 | AR29: 6.1 | BA29: =AL29/SUM($AL29:$AQ29) -> 0.079957356 | BB29: =AM29/SUM($AL29:$AQ29) -> 0.062899787 | BC29: =AN29/SUM($AL29:$AQ29) -> 0.28784648 | BD29: =AO29/SUM($AL29:$AQ29) -> 0.12046908 | BE29: =AP29/SUM($AL29:$AQ29) -> 0.43603412 | BF29: =AQ29/SUM($AL29:$AQ29) -> 0.012793177 | BG29: =#N/A -> #N/A | BH29: Culture | BI29: Culture - AOA | BJ29: Elling et al. (2015) GCA | BK29: Data from original source | BL29: Data from original source | BM29: No | BN29: No | BO29: Not reported; Assumed no brGDGTs (Cultures) | BP29: No | BQ29: Yes | BR29: Fail | BS29: Pass | BT29: Elling et al. (2015) | BU29: Felix | BV29: https://doi.org/10.1016/j.gca.2015.09.004 | BW29: GTDB Release 214.1; NCBI (retrieved from February 21, 2024)
A30: Elling2015_Culture_SCM1_22 | B30: SCM1 | C30: Nitrosopumilus maritimus SCM1 | D30: =INDEX(Strain_IDs!C:C,MATCH(Table1[[#This Row],[Strains]],Strain_IDs!D:D,0)) -> 7 | E30: p__Thermoproteota | F30: c__Nitrososphaeria | G30: o__Nitrososphaerales | H30: f__Nitrosopumilaceae | I30: g__Nitrosopumilus | J30: s__Nitrosopumilus maritimus | K30: p__Nitrososphaerota | L30: c__Nitrososphaeria | M30: o__Nitrosopumilales | N30: f__Nitrosopumilaceae | O30: g__Nitrosopumilus | P30: s__Nitrosopumilus maritimus | Q30: Marine mesophile | R30: Group 1.1a | S30: Group 1.1a-Nitrosopumilus | T30: sequenced | U30: a tropical marine fish tank at the Seattle Aquarium in Seattle | V30: Washington | W30: RR_culture_029 | X30: 22 | Z30: 7.5 | AF30: Culture-temperature | AG30: Total GDGTs | AH30: Total GDGTs; Acid hydrolyzed TLEs (CLs + cleaved IPLs) | AJ30: NP-UHPLC-APCI-qTOF-MS/MS | AK30: =SUM(Table1[[#This Row],[reported_1302]:[reported_1286_iso]]) -> 100.2 | AL30: 25.2 | AM30: 17.1 | AN30: 20.5 | AO30: 5.8 | AP30: 29 | AQ30: 0.4 | AR30: 2.2 | BA30: =AL30/SUM($AL30:$AQ30) -> 0.25714286 | BB30: =AM30/SUM($AL30:$AQ30) -> 0.1744898 | BC30: =AN30/SUM($AL30:$AQ30) -> 0.20918367 | BD30: =AO30/SUM($AL30:$AQ30) -> 0.059183673 | BE30: =AP30/SUM($AL30:$AQ30) -> 0.29591837 | BF30: =AQ30/SUM($AL30:$AQ30) -> 0.0040816327 | BG30: =#N/A -> #N/A | BH30: Culture | BI30: Culture - AOA | BJ30: Elling et al. (2015) GCA | BK30: Data from original source | BL30: Data from original source | BM30: No | BN30: No | BO30: Not reported; Assumed no brGDGTs (Cultures) | BP30: No | BQ30: Yes | BR30: Fail | BS30: Pass | BT30: Elling et al. (2015) | BU30: Felix | BV30: https://doi.org/10.1016/j.gca.2015.09.004 | BW30: GTDB Release 214.1; NCBI (retrieved from February 21, 2024)
A31: Elling2015_Culture_SCM1_25 | B31: SCM1 | C31: Nitrosopumilus maritimus SCM1 | D31: =INDEX(Strain_IDs!C:C,MATCH(Table1[[#This Row],[Strains]],Strain_IDs!D:D,0)) -> 7 | E31: p__Thermoproteota | F31: c__Nitrososphaeria | G31: o__Nitrososphaerales | H31: f__Nitrosopumilaceae | I31: g__Nitrosopumilus | J31: s__Nitrosopumilus maritimus | K31: p__Nitrososphaerota | L31: c__Nitrososphaeria | M31: o__Nitrosopumilales | N31: f__Nitrosopumilaceae | O31: g__Nitrosopumilus | P31: s__Nitrosopumilus maritimus | Q31: Marine mesophile | R31: Group 1.1a | S31: Group 1.1a-Nitrosopumilus | T31: sequenced | U31: a tropical marine fish tank at the Seattle Aquarium in Seattle | V31: Washington | W31: RR_culture_030 | X31: 25 | Z31: 7.5 | AF31: Culture-temperature | AG31: Total GDGTs | AH31: Total GDGTs; Acid hydrolyzed TLEs (CLs + cleaved IPLs) | AJ31: NP-UHPLC-APCI-qTOF-MS/MS | AK31: =SUM(Table1[[#This Row],[reported_1302]:[reported_1286_iso]]) -> 100.1 | AL31: 15.2 | AM31: 12.6 | AN31: 24.3 | AO31: 5.7 | AP31: 38.9 | AQ31: 0.6 | AR31: 2.8 | BA31: =AL31/SUM($AL31:$AQ31) -> 0.15621788 | BB31: =AM31/SUM($AL31:$AQ31) -> 0.1294964 | BC31: =AN31/SUM($AL31:$AQ31) -> 0.24974306 | BD31: =AO31/SUM($AL31:$AQ31) -> 0.058581706 | BE31: =AP31/SUM($AL31:$AQ31) -> 0.39979445 | BF31: =AQ31/SUM($AL31:$AQ31) -> 0.0061664954 | BG31: =#N/A -> #N/A | BH31: Culture | BI31: Culture - AOA | BJ31: Elling et al. (2015) GCA | BK31: Data from original source | BL31: Data from original source | BM31: No | BN31: No | BO31: Not reported; Assumed no brGDGTs (Cultures) | BP31: No | BQ31: Yes | BR31: Fail | BS31: Pass | BT31: Elling et al. (2015) | BU31: Felix | BV31: https://doi.org/10.1016/j.gca.2015.09.004 | BW31: GTDB Release 214.1; NCBI (retrieved from February 21, 2024)
A32: Elling2015_Culture_SCM1_28 | B32: SCM1 | C32: Nitrosopumilus maritimus SCM1 | D32: =INDEX(Strain_IDs!C:C,MATCH(Table1[[#This Row],[Strains]],Strain_IDs!D:D,0)) -> 7 | E32: p__Thermoproteota | F32: c__Nitrososphaeria | G32: o__Nitrososphaerales | H32: f__Nitrosopumilaceae | I32: g__Nitrosopumilus | J32: s__Nitrosopumilus maritimus | K32: p__Nitrososphaerota | L32: c__Nitrososphaeria | M32: o__Nitrosopumilales | N32: f__Nitrosopumilaceae | O32: g__Nitrosopumilus | P32: s__Nitrosopumilus maritimus | Q32: Marine mesophile | R32: Group 1.1a | S32: Group 1.1a-Nitrosopumilus | T32: sequenced | U32: a tropical marine fish tank at the Seattle Aquarium in Seattle | V32: Washington | W32: RR_culture_031 | X32: 28 | Z32: 7.5 | AF32: Culture-temperature | AG32: Total GDGTs | AH32: Total GDGTs; Acid hydrolyzed TLEs (CLs + cleaved IPLs) | AJ32: NP-UHPLC-APCI-qTOF-MS/MS | AK32: =SUM(Table1[[#This Row],[reported_1302]:[reported_1286_iso]]) -> 100.1 | AL32: 12.1 | AM32: 10 | AN32: 26.6 | AO32: 9.5 | AP32: 35.7 | AQ32: 0.9 | AR32: 5.3 | BA32: =AL32/SUM($AL32:$AQ32) -> 0.12763713 | BB32: =AM32/SUM($AL32:$AQ32) -> 0.10548523 | BC32: =AN32/SUM($AL32:$AQ32) -> 0.28059072 | BD32: =AO32/SUM($AL32:$AQ32) -> 0.10021097 | BE32: =AP32/SUM($AL32:$AQ32) -> 0.37658228 | BF32: =AQ32/SUM($AL32:$AQ32) -> 0.0094936709 | BG32: =#N/A -> #N/A | BH32: Culture | BI32: Culture - AOA | BJ32: Elling et al. (2015) GCA | BK32: Data from original source | BL32: Data from original source | BM32: No | BN32: No | BO32: Not reported; Assumed no brGDGTs (Cultures) | BP32: No | BQ32: Yes | BR32: Fail | BS32: Pass | BT32: Elling et al. (2015) | BU32: Felix | BV32: https://doi.org/10.1016/j.gca.2015.09.004 | BW32: GTDB Release 214.1; NCBI (retrieved from February 21, 2024)
